Workbook

Sheet tableau de bord sécurité 2026
A1: Objet | C1: CDLA | E1: DAME AF | J1: DAME BD | L1: DES AB | R1: CMPP DREUX | T1: CMPP | U1: CMPP | W1: DITEP | Z1: PISP
E2: SEES | F2: SIPFP | G2: Clémenceau | H2: Internat | L2: NLR | M2: Internat | N2: Antenne CHARTRES | O2: Antenne VERNOUILLET | P2: 2SAI | T2: CHARTRES | U2: CHATEAUDUN | W2: SENONCHES | X2: MORANCEZ | Z2: DDAISP | AA2: GEM | AB2: ESATHM
A3: Commission de sécurité | B3: PV | C3: =CDLA!C3 -> X | E3: ='DAME-AF-SEES'!C3 -> Présent | F3: ='DAME-AF-SIPFP'!C3 -> Présent | G3: ='DAME-AF+GEM-Clémenceau'!C3 -> X | H3: ='DAME-AF-Internat'!C3 -> X | J3: ='DAME-BD'!C3 -> X | L3: ='DES-AB-NLR'!C3 -> X | M3: ='DES-AB-Internat'!C3 -> 44986 | N3: X | O3: ='DES-AB-VERNOUILLET'!C3 -> NC | P3: ='DES-AB-2SAI'!C3 -> NC | R3: ='CMPP-DREUX'!C3 -> NC | T3: ='CMPP-CHARTRES'!C3 -> présent | U3: ='CMPP-CHATEAUDUN'!C3 -> NC | W3: ='DITEP-SENONCHES'!C3 -> 45721 | X3: ='DITEP-MORANCEZ'!C3 -> 45581 | Z3: ='PISP-DDAISP-ESATHM'!C3 -> NC | AA3: ='PIPSP habitat inclusif'!C3 -> X Pas d'obligation | AB3: X
A4: Triennale | B4: contrôle | C4: =CDLA!C4 -> X | E4: ='DAME-AF-SEES'!C4 -> X | F4: ='DAME-AF-SIPFP'!C4 -> X | G4: ='DAME-AF+GEM-Clémenceau'!C4 -> X | H4: ='DAME-AF-Internat'!C4 -> X | J4: ='DAME-BD'!C4 -> X | L4: ='DES-AB-NLR'!C4 -> X | M4: ='DES-AB-Internat'!C4 -> 45047 | N4: ='DES-AB-CHARTRES'!C4 -> X | O4: ='DES-AB-VERNOUILLET'!C4 -> X | P4: ='DES-AB-2SAI'!C4 -> X | R4: ='CMPP-DREUX'!C4 -> X | T4: ='CMPP-CHARTRES'!C4 -> X | U4: ='CMPP-CHATEAUDUN'!C4 -> X | W4: ='DITEP-SENONCHES'!C4 -> 46007 | X4: ='DITEP-MORANCEZ'!C4 -> 45231 | Z4: ='PISP-DDAISP-ESATHM'!C4 -> X | AA4: ='PIPSP habitat inclusif'!C4 -> X Pas d'obligation | AB4: X
A5: alarme incendie | B5: entretien | C5: =CDLA!C5 -> 0 | E5: ='DAME-AF-SEES'!C5 -> 46041 | F5: ='DAME-AF-SIPFP'!C5 -> 46028 | G5: ='DAME-AF+GEM-Clémenceau'!C5 -> 45988 | H5: ='DAME-AF-Internat'!C5 -> X | J5: ='DAME-BD'!C5 -> 45728 | L5: ='DES-AB-NLR'!C5 -> 45717 | M5: ='DES-AB-Internat'!C5 -> 45981 | N5: ='DES-AB-CHARTRES'!C5 -> 45911 | O5: ='DES-AB-VERNOUILLET'!C5 -> 45911 | P5: ='DES-AB-2SAI'!C5 -> 45911 | R5: ='CMPP-DREUX'!C5 -> 45566 | T5: ='CMPP-CHARTRES'!C5 -> 46037 | U5: ='CMPP-CHATEAUDUN'!C5 -> 46043 | W5: ='DITEP-SENONCHES'!C5 -> 45952 | X5: ='DITEP-MORANCEZ'!C5 -> 45790 | Z5: ='PISP-DDAISP-ESATHM'!C5 -> 45917 | AA5: ='PIPSP habitat inclusif'!C5 -> X Pas d'obligation | AB5: X
A6: Extinteurs | B6: entretien | C6: =CDLA!C6 -> 45590 | E6: ='DAME-AF-SEES'!C6 -> 45624 | F6: ='DAME-AF-SIPFP'!C6 -> 45597 | G6: ='DAME-AF+GEM-Clémenceau'!C6 -> 45614 | H6: ='DAME-AF-Internat'!C6 -> X | J6: ='DAME-BD'!C6 -> 45505 | L6: ='DES-AB-NLR'!C6 -> 45689 | M6: ='DES-AB-Internat'!C6 -> 45712 | N6: ='DES-AB-CHARTRES'!C6 -> 45689 | O6: ='DES-AB-VERNOUILLET'!C6 -> 45689 | P6: ='DES-AB-2SAI'!C6 -> 45689 | R6: ='CMPP-DREUX'!C6 -> 45536 | T6: ='CMPP-CHARTRES'!C6 -> 45686 | U6: ='CMPP-CHATEAUDUN'!C6 -> 44682 | W6: ='DITEP-SENONCHES'!C6 -> 46055 | X6: ='DITEP-MORANCEZ'!C6 -> 46035 | Z6: ='PISP-DDAISP-ESATHM'!C6 -> 45952 | AA6: ='PIPSP habitat inclusif'!C6 -> X Pas d'obligation | AB6: X
A7: Désenfumage | B7: entretien | C7: =CDLA!C7 -> X | E7: ='DAME-AF-SEES'!C7 -> X | F7: ='DAME-AF-SIPFP'!C7 -> X | G7: ='DAME-AF+GEM-Clémenceau'!C7 -> X | H7: ='DAME-AF-Internat'!C7 -> X | J7: ='DAME-BD'!C7 -> X | L7: ='DES-AB-NLR'!C7 -> 45689 | M7: ='DES-AB-Internat'!C7 -> 45712 | N7: ='DES-AB-CHARTRES'!C7 -> 45689 | O7: ='DES-AB-VERNOUILLET'!C7 -> X | P7: ='DES-AB-2SAI'!C7 -> X | R7: ='CMPP-DREUX'!C7 -> X | T7: ='CMPP-CHARTRES'!C7 -> X | U7: ='CMPP-CHATEAUDUN'!C7 -> X | W7: ='DITEP-SENONCHES'!C7 -> 45825 | X7: ='DITEP-MORANCEZ'!C7 -> X | Z7: ='PISP-DDAISP-ESATHM'!C7 -> X | AA7: ='PIPSP habitat inclusif'!C7 -> X Pas d'obligation | AB7: X
A8: Exercices incendie | B8: 1 | C8: =CDLA!C8 -> 45575 | E8: ='DAME-AF-SEES'!C8 -> 45923 | F8: ='DAME-AF-SIPFP'!C8 -> 45923 | G8: ='DAME-AF+GEM-Clémenceau'!C8 -> 45923 | H8: ='DAME-AF-Internat'!C8 -> 45931 | J8: ='DAME-BD'!C8 -> 45930 | L8: ='DES-AB-NLR'!C8 -> 45536 | M8: ='DES-AB-Internat'!C8 -> 45903 | N8: ='DES-AB-CHARTRES'!C8 -> 45911 | O8: ='DES-AB-VERNOUILLET'!C8 -> 45911 | P8: ='DES-AB-2SAI'!C8 -> 45911 | R8: ='CMPP-DREUX'!C8 -> 45925 | T8: ='CMPP-CHARTRES'!C8 -> 45540 | U8: ='CMPP-CHATEAUDUN'!C8 -> 43344 | W8: ='DITEP-SENONCHES'!C8 -> 45692 | X8: ='DITEP-MORANCEZ'!C8 -> 45597 | Z8: ='PISP-DDAISP-ESATHM'!C8 -> 45909 | AA8: ='PIPSP habitat inclusif'!C8 -> X Pas d'obligation | AB8: X
B9: 2 | C9: =CDLA!C9 -> 45744 | E9: ='DAME-AF-SEES'!C9 -> 45803 | F9: ='DAME-AF-SIPFP'!C9 -> 45678 | G9: ='DAME-AF+GEM-Clémenceau'!C9 -> 45680 | H9: ='DAME-AF-Internat'!C9 -> 46087 | J9: ='DAME-BD'!C9 -> 45744 | L9: ='DES-AB-NLR'!C9 -> 45717 | M9: ='DES-AB-Internat'!C9 -> 46087 | N9: ='DES-AB-CHARTRES'!C9 -> 46093 | O9: ='DES-AB-VERNOUILLET'!C9 -> 46093 | P9: ='DES-AB-2SAI'!C9 -> 46093 | R9: ='CMPP-DREUX'!C9 -> 0 | T9: ='CMPP-CHARTRES'!C9 -> 46114 | U9: ='CMPP-CHATEAUDUN'!C9 -> 0 | W9: ='DITEP-SENONCHES'!C9 -> 46098 | X9: ='DITEP-MORANCEZ'!C9 -> 45721 | Z9: ='PISP-DDAISP-ESATHM'!C9 -> 0 | AA9: ='PIPSP habitat inclusif'!C9 -> X Pas d'obligation | AB9: X
A10: Exercices PPMS | B10: 1 | C10: =CDLA!C10 -> 0 | E10: ='DAME-AF-SEES'!C10 -> 45943 | F10: ='DAME-AF-SIPFP'!C10 -> 45943 | G10: ='DAME-AF+GEM-Clémenceau'!C10 -> 45943 | H10: ='DAME-AF-Internat'!C10 -> 45931 | J10: ='DAME-BD'!C10 -> 45943 | L10: ='DES-AB-NLR'!C10 -> 45936 | M10: ='DES-AB-Internat'!C10 -> 45931 | N10: ='DES-AB-CHARTRES'!C10 -> 45939 | O10: ='DES-AB-VERNOUILLET'!C10 -> 45939 | P10: ='DES-AB-2SAI'!C10 -> 45939 | R10: ='CMPP-DREUX'!C10 -> 0 | T10: ='CMPP-CHARTRES'!C10 -> 45924 | U10: ='CMPP-CHATEAUDUN'!C10 -> 0 | W10: ='DITEP-SENONCHES'!C10 -> 45981 | X10: ='DITEP-MORANCEZ'!C10 -> 46003 | Z10: ='PISP-DDAISP-ESATHM'!C10 -> 43617 | AA10: ='PIPSP habitat inclusif'!C10 -> X Pas d'obligation | AB10: X
B11: 2 | C11: =CDLA!C11 -> 0 | E11: ='DAME-AF-SEES'!C11 -> 0 | F11: ='DAME-AF-SIPFP'!C11 -> 0 | G11: ='DAME-AF+GEM-Clémenceau'!C11 -> 0 | H11: ='DAME-AF-Internat'!C11 -> 46146 | J11: ='DAME-BD'!C11 -> 45671 | L11: ='DES-AB-NLR'!C11 -> 46097 | M11: ='DES-AB-Internat'!C11 -> 46146 | N11: ='DES-AB-CHARTRES'!C11 -> 45750 | O11: ='DES-AB-VERNOUILLET'!C11 -> 45777 | P11: ='DES-AB-2SAI'!C11 -> 45750 | R11: ='CMPP-DREUX'!C11 -> 0 | T11: ='CMPP-CHARTRES'!C11 -> 46128 | U11: ='CMPP-CHATEAUDUN'!C11 -> 0 | W11: ='DITEP-SENONCHES'!C11 -> 0 | X11: ='DITEP-MORANCEZ'!C11 -> 46107 | Z11: ='PISP-DDAISP-ESATHM'!C11 -> 0 | AA11: ='PIPSP habitat inclusif'!C11 -> X Pas d'obligation | AB11: X
A12: calage des dates d'exercices de l'année scolaire | B12: date butoir fin Août | C12: =CDLA!C12 -> 45444 | E12: ='DAME-AF-SEES'!C12 -> 45809 | F12: ='DAME-AF-SIPFP'!C12 -> 45809 | G12: ='DAME-AF+GEM-Clémenceau'!C12 -> 45809 | H12: ='DAME-AF-Internat'!C12 -> 45809 | J12: ='DAME-BD'!C12 -> 45809 | L12: ='DES-AB-NLR'!C12 -> 45809 | M12: ='DES-AB-Internat'!C12 -> 46174 | N12: ='DES-AB-CHARTRES'!C12 -> 45809 | O12: ='DES-AB-VERNOUILLET'!C12 -> 45809 | P12: ='DES-AB-2SAI'!C12 -> 45809 | R12: ='CMPP-DREUX'!C12 -> 45809 | T12: ='CMPP-CHARTRES'!C12 -> 45809 | U12: ='CMPP-CHATEAUDUN'!C12 -> 45444 | W12: ='DITEP-SENONCHES'!C12 -> 45809 | X12: ='DITEP-MORANCEZ'!C12 -> 45809 | Z12: ='PISP-DDAISP-ESATHM'!C12 -> 45809 | AA12: ='PIPSP habitat inclusif'!C12 -> X Pas d'obligation | AB12: X
A13: Électricité | B13: vérification | C13: =CDLA!C13 -> 45301 | E13: ='DAME-AF-SEES'!C13 -> 46041 | F13: ='DAME-AF-SIPFP'!C13 -> 46041 | G13: ='DAME-AF+GEM-Clémenceau'!C13 -> 46041 | H13: ='DAME-AF-Internat'!C13 -> 45757 | J13: ='DAME-BD'!C13 -> 46077 | L13: ='DES-AB-NLR'!C13 -> 45897 | M13: ='DES-AB-Internat'!C13 -> 46121 | N13: ='DES-AB-CHARTRES'!C13 -> 45366 | O13: ='DES-AB-VERNOUILLET'!C13 -> 45828 | P13: ='DES-AB-2SAI'!C13 -> 45715 | R13: ='CMPP-DREUX'!C13 -> 45898 | T13: ='CMPP-CHARTRES'!C13 -> 46037 | U13: ='CMPP-CHATEAUDUN'!C13 -> 46043 | W13: ='DITEP-SENONCHES'!C13 -> 45835 | X13: ='DITEP-MORANCEZ'!C13 -> 45919 | Z13: ='PISP-DDAISP-ESATHM'!C13 -> 45925 | AA13: ='PIPSP habitat inclusif'!C13 -> X Pas d'obligation | AB13: X
A14: blocs de secours (internat mensuel) | B14: vérification | C14: =CDLA!C14 -> X | E14: ='DAME-AF-SEES'!C14 -> X | F14: ='DAME-AF-SIPFP'!C14 -> X | G14: ='DAME-AF+GEM-Clémenceau'!C14 -> X | H14: ='DAME-AF-Internat'!C14 -> X | J14: ='DAME-BD'!C14 -> X | L14: ='DES-AB-NLR'!C14 -> X | M14: ='DES-AB-Internat'!C14 -> 46030 | N14: ='DES-AB-CHARTRES'!C14 -> X | O14: ='DES-AB-VERNOUILLET'!C14 -> X | P14: ='DES-AB-2SAI'!C14 -> X | R14: ='CMPP-DREUX'!C14 -> X | T14: ='CMPP-CHARTRES'!C14 -> X | U14: ='CMPP-CHATEAUDUN'!C14 -> X | W14: ='DITEP-SENONCHES'!C14 -> 45952 | X14: ='DITEP-MORANCEZ'!C14 -> 0 | Z14: ='PISP-DDAISP-ESATHM'!C14 -> X | AA14: ='PIPSP habitat inclusif'!C14 -> X Pas d'obligation | AB14: X
A15: Ascenseur | B15: entretien | C15: =CDLA!C15 -> X | E15: ='DAME-AF-SEES'!C15 -> X | F15: ='DAME-AF-SIPFP'!C15 -> X | G15: ='DAME-AF+GEM-Clémenceau'!C15 -> X | H15: ='DAME-AF-Internat'!C15 -> X | J15: ='DAME-BD'!C15 -> X | L15: ='DES-AB-NLR'!C15 -> X | M15: ='DES-AB-Internat'!C15 -> X | N15: ='DES-AB-CHARTRES'!C15 -> X | O15: ='DES-AB-VERNOUILLET'!C15 -> X | P15: ='DES-AB-2SAI'!C15 -> X | R15: ='CMPP-DREUX'!C15 -> X | T15: ='CMPP-CHARTRES'!C15 -> X | U15: ='CMPP-CHATEAUDUN'!C15 -> X | W15: ='DITEP-SENONCHES'!C15 -> 45617 | X15: ='DITEP-MORANCEZ'!C15 -> X | Z15: ='PISP-DDAISP-ESATHM'!C15 -> 45727 | AA15: ='PIPSP habitat inclusif'!C15 -> X Pas d'obligation | AB15: X
B16: vérification | C16: =CDLA!C16 -> X | E16: ='DAME-AF-SEES'!C16 -> X | F16: ='DAME-AF-SIPFP'!C16 -> X | G16: ='DAME-AF+GEM-Clémenceau'!C16 -> X | H16: ='DAME-AF-Internat'!C16 -> X | J16: ='DAME-BD'!C16 -> X | L16: ='DES-AB-NLR'!C16 -> X | M16: ='DES-AB-Internat'!C16 -> X | N16: ='DES-AB-CHARTRES'!C16 -> X | O16: ='DES-AB-VERNOUILLET'!C16 -> X | P16: ='DES-AB-2SAI'!C16 -> X | R16: ='CMPP-DREUX'!C16 -> X | T16: ='CMPP-CHARTRES'!C16 -> X | U16: ='CMPP-CHATEAUDUN'!C16 -> X | W16: ='DITEP-SENONCHES'!C16 -> 45966 | X16: ='DITEP-MORANCEZ'!C16 -> X | Z16: ='PISP-DDAISP-ESATHM'!C16 -> 0 | AA16: ='PIPSP habitat inclusif'!C16 -> X Pas d'obligation | AB16: X
A17: Quinquenale | B17: contrôle | C17: =CDLA!C17 -> X | E17: ='DAME-AF-SEES'!C17 -> X | F17: ='DAME-AF-SIPFP'!C17 -> X | G17: ='DAME-AF+GEM-Clémenceau'!C17 -> X | H17: ='DAME-AF-Internat'!C17 -> X | J17: ='DAME-BD'!C17 -> X | L17: ='DES-AB-NLR'!C17 -> X | M17: ='DES-AB-Internat'!C17 -> X | N17: ='DES-AB-CHARTRES'!C17 -> X | O17: ='DES-AB-VERNOUILLET'!C17 -> X | P17: ='DES-AB-2SAI'!C17 -> X | R17: ='CMPP-DREUX'!C17 -> X | T17: ='CMPP-CHARTRES'!C17 -> X | U17: ='CMPP-CHATEAUDUN'!C17 -> X | W17: ='DITEP-SENONCHES'!C17 -> 45689 | X17: ='DITEP-MORANCEZ'!C17 -> X | Z17: ='PISP-DDAISP-ESATHM'!C17 -> 46041 | AA17: ='PIPSP habitat inclusif'!C17 -> X Pas d'obligation | AB17: X
A18: Élévateur | B18: entretien | C18: =CDLA!C18 -> X | E18: ='DAME-AF-SEES'!C18 -> X | F18: ='DAME-AF-SIPFP'!C18 -> X | G18: ='DAME-AF+GEM-Clémenceau'!C18 -> X | H18: ='DAME-AF-Internat'!C18 -> X | J18: ='DAME-BD'!C18 -> X | L18: ='DES-AB-NLR'!C18 -> X | M18: ='DES-AB-Internat'!C18 -> X | N18: ='DES-AB-CHARTRES'!C18 -> 45925 | O18: ='DES-AB-VERNOUILLET'!C18 -> X | P18: ='DES-AB-2SAI'!C18 -> X | R18: ='CMPP-DREUX'!C18 -> X | T18: ='CMPP-CHARTRES'!C18 -> X | U18: ='CMPP-CHATEAUDUN'!C18 -> X | W18: ='DITEP-SENONCHES'!C18 -> X | X18: ='DITEP-MORANCEZ'!C18 -> X | Z18: ='PISP-DDAISP-ESATHM'!C18 -> X | AA18: ='PIPSP habitat inclusif'!C18 -> X Pas d'obligation | AB18: X
B19: vérification | C19: =CDLA!C19 -> X | E19: ='DAME-AF-SEES'!C19 -> X | F19: ='DAME-AF-SIPFP'!C19 -> X | G19: ='DAME-AF+GEM-Clémenceau'!C19 -> X | H19: ='DAME-AF-Internat'!C19 -> X | J19: ='DAME-BD'!C19 -> X | L19: ='DES-AB-NLR'!C19 -> X | M19: ='DES-AB-Internat'!C19 -> X | N19: ='DES-AB-CHARTRES'!C19 -> 45631 | O19: ='DES-AB-VERNOUILLET'!C19 -> X | P19: ='DES-AB-2SAI'!C19 -> X | R19: ='CMPP-DREUX'!C19 -> X | T19: ='CMPP-CHARTRES'!C19 -> X | U19: ='CMPP-CHATEAUDUN'!C19 -> X | W19: ='DITEP-SENONCHES'!C19 -> X | X19: ='DITEP-MORANCEZ'!C19 -> X | Z19: ='PISP-DDAISP-ESATHM'!C19 -> X | AA19: ='PIPSP habitat inclusif'!C19 -> X Pas d'obligation | AB19: X
A20: Portail | B20: vérification | C20: =CDLA!C20 -> X | E20: ='DAME-AF-SEES'!C20 -> 45701 | F20: ='DAME-AF-SIPFP'!C20 -> 45701 | G20: ='DAME-AF+GEM-Clémenceau'!C20 -> X | H20: ='DAME-AF-Internat'!C20 -> X | J20: ='DAME-BD'!C20 -> X | L20: ='DES-AB-NLR'!C20 -> 45658 | M20: ='DES-AB-Internat'!C20 -> X | N20: ='DES-AB-CHARTRES'!C20 -> 45627 | O20: ='DES-AB-VERNOUILLET'!C20 -> X | P20: ='DES-AB-2SAI'!C20 -> X | R20: ='CMPP-DREUX'!C20 -> X | T20: ='CMPP-CHARTRES'!C20 -> X | U20: ='CMPP-CHATEAUDUN'!C20 -> X | W20: ='DITEP-SENONCHES'!C20 -> 45692 | X20: ='DITEP-MORANCEZ'!C20 -> 46122 | Z20: ='PISP-DDAISP-ESATHM'!C20 -> X | AA20: ='PIPSP habitat inclusif'!C20 -> X Pas d'obligation | AB20: X
A21: Groupe électrogène | B21: entretien | C21: =CDLA!C21 -> X | E21: ='DAME-AF-SEES'!C21 -> X | F21: ='DAME-AF-SIPFP'!C21 -> X | G21: ='DAME-AF+GEM-Clémenceau'!C21 -> X | H21: ='DAME-AF-Internat'!C21 -> X | J21: ='DAME-BD'!C21 -> X | L21: ='DES-AB-NLR'!C21 -> 45965 | M21: ='DES-AB-Internat'!C21 -> X | N21: ='DES-AB-CHARTRES'!C21 -> X | O21: ='DES-AB-VERNOUILLET'!C21 -> X | P21: ='DES-AB-2SAI'!C21 -> X | R21: ='CMPP-DREUX'!C21 -> X | T21: ='CMPP-CHARTRES'!C21 -> X | U21: ='CMPP-CHATEAUDUN'!C21 -> X | W21: ='DITEP-SENONCHES'!C21 -> X | X21: ='DITEP-MORANCEZ'!C21 -> X | Z21: ='PISP-DDAISP-ESATHM'!C21 -> X | AA21: ='PIPSP habitat inclusif'!C21 -> X Pas d'obligation | AB21: X
A22: Jeux exterieur | B22: vérification | C22: =CDLA!C22 -> X | E22: ='DAME-AF-SEES'!C22 -> 45686 | F22: ='DAME-AF-SIPFP'!C22 -> X | G22: ='DAME-AF+GEM-Clémenceau'!C22 -> X | H22: ='DAME-AF-Internat'!C22 -> X | J22: ='DAME-BD'!C22 -> 45821 | L22: ='DES-AB-NLR'!C22 -> 45658 | M22: ='DES-AB-Internat'!C22 -> X | N22: ='DES-AB-CHARTRES'!C22 -> X | O22: ='DES-AB-VERNOUILLET'!C22 -> X | P22: ='DES-AB-2SAI'!C22 -> X | R22: ='CMPP-DREUX'!C22 -> X | T22: ='CMPP-CHARTRES'!C22 -> X | U22: ='CMPP-CHATEAUDUN'!C22 -> X | W22: ='DITEP-SENONCHES'!C22 -> X | X22: ='DITEP-MORANCEZ'!C22 -> X | Z22: ='PISP-DDAISP-ESATHM'!C22 -> X | AA22: ='PIPSP habitat inclusif'!C22 -> X Pas d'obligation | AB22: X
A23: Mur d'escalade | B23: vérification | C23: =CDLA!C23 -> X | E23: ='DAME-AF-SEES'!C23 -> X | F23: ='DAME-AF-SIPFP'!C23 -> X | G23: ='DAME-AF+GEM-Clémenceau'!C23 -> X | H23: ='DAME-AF-Internat'!C23 -> X | J23: ='DAME-BD'!C23 -> X | L23: ='DES-AB-NLR'!C23 -> 45413 | M23: ='DES-AB-Internat'!C23 -> X | N23: ='DES-AB-CHARTRES'!C23 -> X | O23: ='DES-AB-VERNOUILLET'!C23 -> X | P23: ='DES-AB-2SAI'!C23 -> X | R23: ='CMPP-DREUX'!C23 -> X | T23: ='CMPP-CHARTRES'!C23 -> X | U23: ='CMPP-CHATEAUDUN'!C23 -> X | W23: ='DITEP-SENONCHES'!C23 -> X | X23: ='DITEP-MORANCEZ'!C23 -> X | Z23: ='PISP-DDAISP-ESATHM'!C23 -> X | AA23: ='PIPSP habitat inclusif'!C23 -> X Pas d'obligation | AB23: X
A24: Chaufferie | B24: ramonage | C24: =CDLA!C24 -> X | E24: ='DAME-AF-SEES'!C24 -> 45751 | F24: ='DAME-AF-SIPFP'!C24 -> 45751 | G24: ='DAME-AF+GEM-Clémenceau'!C24 -> 1 | H24: ='DAME-AF-Internat'!C24 -> X | J24: ='DAME-BD'!C24 -> X | L24: ='DES-AB-NLR'!C24 -> 45845 | M24: ='DES-AB-Internat'!C24 -> X | N24: ='DES-AB-CHARTRES'!C24 -> 1 | O24: ='DES-AB-VERNOUILLET'!C24 -> 0 | P24: ='DES-AB-2SAI'!C24 -> X | R24: ='CMPP-DREUX'!C24 -> 45352 | T24: ='CMPP-CHARTRES'!C24 -> X | U24: ='CMPP-CHATEAUDUN'!C24 -> X | W24: ='DITEP-SENONCHES'!C24 -> 45825 | X24: ='DITEP-MORANCEZ'!C24 -> 0 | Z24: ='PISP-DDAISP-ESATHM'!C24 -> 45748 | AA24: ='PIPSP habitat inclusif'!C24 -> X Pas d'obligation | AB24: X
A25: Disconnecteur | B25: vérification | C25: =CDLA!C25 -> X | E25: ='DAME-AF-SEES'!C25 -> 45912 | F25: ='DAME-AF-SIPFP'!C25 -> X | G25: ='DAME-AF+GEM-Clémenceau'!C25 -> X | H25: ='DAME-AF-Internat'!C25 -> X | J25: ='DAME-BD'!C25 -> X | L25: ='DES-AB-NLR'!C25 -> 45910 | M25: ='DES-AB-Internat'!C25 -> X | N25: ='DES-AB-CHARTRES'!C25 -> X | O25: ='DES-AB-VERNOUILLET'!C25 -> 0 | P25: ='DES-AB-2SAI'!C25 -> X | R25: ='CMPP-DREUX'!C25 -> 45944 | T25: ='CMPP-CHARTRES'!C25 -> X | U25: ='CMPP-CHATEAUDUN'!C25 -> X | W25: ='DITEP-SENONCHES'!C25 -> 45444 | X25: ='DITEP-MORANCEZ'!C25 -> 45919 | Z25: ='PISP-DDAISP-ESATHM'!C25 -> 0 | AA25: ='PIPSP habitat inclusif'!C25 -> X Pas d'obligation | AB25: X
A26: Gaz | B26: vérification | C26: =CDLA!C26 -> X | E26: ='DAME-AF-SEES'!C26 -> 45692 | F26: ='DAME-AF-SIPFP'!C26 -> 46043 | G26: ='DAME-AF+GEM-Clémenceau'!C26 -> X | H26: ='DAME-AF-Internat'!C26 -> X | J26: ='DAME-BD'!C26 -> X | L26: ='DES-AB-NLR'!C26 -> 45924 | M26: ='DES-AB-Internat'!C26 -> X | N26: ='DES-AB-CHARTRES'!C26 -> 45975 | O26: ='DES-AB-VERNOUILLET'!C26 -> 0 | P26: ='DES-AB-2SAI'!C26 -> X | R26: ='CMPP-DREUX'!C26 -> 45944 | T26: ='CMPP-CHARTRES'!C26 -> X | U26: ='CMPP-CHATEAUDUN'!C26 -> X | W26: ='DITEP-SENONCHES'!C26 -> 45658 | X26: ='DITEP-MORANCEZ'!C26 -> 45919 | Z26: ='PISP-DDAISP-ESATHM'!C26 -> 45925 | AA26: ='PIPSP habitat inclusif'!C26 -> X Pas d'obligation | AB26: X
A27: CTA | B27: entretien | C27: =CDLA!C27 -> X | E27: ='DAME-AF-SEES'!C27 -> X | F27: ='DAME-AF-SIPFP'!C27 -> X | G27: ='DAME-AF+GEM-Clémenceau'!C27 -> X | H27: ='DAME-AF-Internat'!C27 -> X | J27: ='DAME-BD'!C27 -> 0 | L27: ='DES-AB-NLR'!C27 -> X | M27: ='DES-AB-Internat'!C27 -> X | N27: ='DES-AB-CHARTRES'!C27 -> X | O27: ='DES-AB-VERNOUILLET'!C27 -> X | P27: ='DES-AB-2SAI'!C27 -> X | R27: ='CMPP-DREUX'!C27 -> X | T27: ='CMPP-CHARTRES'!C27 -> 45831 | U27: ='CMPP-CHATEAUDUN'!C27 -> X | W27: ='DITEP-SENONCHES'!C27 -> X | X27: ='DITEP-MORANCEZ'!C27 -> 45750 | Z27: ='PISP-DDAISP-ESATHM'!C27 -> X | AA27: ='PIPSP habitat inclusif'!C27 -> X Pas d'obligation | AB27: X
B28: vérification | C28: =CDLA!C28 -> X | E28: ='DAME-AF-SEES'!C28 -> X | F28: ='DAME-AF-SIPFP'!C28 -> X | G28: ='DAME-AF+GEM-Clémenceau'!C28 -> X | H28: ='DAME-AF-Internat'!C28 -> X | J28: ='DAME-BD'!C28 -> 0 | L28: ='DES-AB-NLR'!C28 -> X | M28: ='DES-AB-Internat'!C28 -> X | N28: ='DES-AB-CHARTRES'!C28 -> X | O28: ='DES-AB-VERNOUILLET'!C28 -> X | P28: ='DES-AB-2SAI'!C28 -> X | R28: ='CMPP-DREUX'!C28 -> X | T28: ='CMPP-CHARTRES'!C28 -> 0 | U28: ='CMPP-CHATEAUDUN'!C28 -> X | W28: ='DITEP-SENONCHES'!C28 -> X | X28: ='DITEP-MORANCEZ'!C28 -> 0 | Z28: ='PISP-DDAISP-ESATHM'!C28 -> X | AA28: ='PIPSP habitat inclusif'!C28 -> X Pas d'obligation | AB28: X
A29: Plans d'intervention | C29: =CDLA!C29 -> 45832 | E29: ='DAME-AF-SEES'!C29 -> 45989 | F29: ='DAME-AF-SIPFP'!C29 -> 45658 | G29: ='DAME-AF+GEM-Clémenceau'!C29 -> 0 | H29: ='DAME-AF-Internat'!C29 -> X | J29: ='DAME-BD'!C29 -> 45812 | L29: ='DES-AB-NLR'!C29 -> 45809 | M29: ='DES-AB-Internat'!C29 -> 45809 | N29: ='DES-AB-CHARTRES'!C29 -> 0 | O29: ='DES-AB-VERNOUILLET'!C29 -> 45809 | P29: ='DES-AB-2SAI'!C29 -> 0 | R29: ='CMPP-DREUX'!C29 -> 45811 | T29: ='CMPP-CHARTRES'!C29 -> 0 | U29: ='CMPP-CHATEAUDUN'!C29 -> 0 | W29: ='DITEP-SENONCHES'!C29 -> 0 | X29: ='DITEP-MORANCEZ'!C29 -> 45861 | Z29: ='PISP-DDAISP-ESATHM'!C29 -> 45846 | AA29: ='PIPSP habitat inclusif'!C29 -> X Pas d'obligation | AB29: X
A30: Plans des abords extérieur (point de rassemblement et circulation) | C30: =CDLA!C30 -> 45832 | E30: ='DAME-AF-SEES'!C30 -> 0 | F30: ='DAME-AF-SIPFP'!C30 -> 45658 | G30: ='DAME-AF+GEM-Clémenceau'!C30 -> 0 | H30: ='DAME-AF-Internat'!C30 -> X | J30: ='DAME-BD'!C30 -> 45804 | L30: ='DES-AB-NLR'!C30 -> 45809 | M30: ='DES-AB-Internat'!C30 -> 45809 | N30: ='DES-AB-CHARTRES'!C30 -> 0 | O30: ='DES-AB-VERNOUILLET'!C30 -> 0 | P30: ='DES-AB-2SAI'!C30 -> 0 | R30: ='CMPP-DREUX'!C30 -> 45811 | T30: ='CMPP-CHARTRES'!C30 -> 0 | U30: ='CMPP-CHATEAUDUN'!C30 -> X | W30: ='DITEP-SENONCHES'!C30 -> 0 | X30: ='DITEP-MORANCEZ'!C30 -> 45861 | Z30: ='PISP-DDAISP-ESATHM'!C30 -> 45846 | AA30: ='PIPSP habitat inclusif'!C30 -> X Pas d'obligation | AB30: X
A31: Personnel SST | B31: formation | C31: =CDLA!C31 -> 0 | E31: ='DAME-AF-SEES'!C31 -> 45698 | F31: ='DAME-AF-SIPFP'!C31 -> 45698 | G31: ='DAME-AF+GEM-Clémenceau'!C31 -> 1 | H31: ='DAME-AF-Internat'!C31 -> 0 | J31: ='DAME-BD'!C31 -> 45964 | L31: ='DES-AB-NLR'!C31 -> 45627 | M31: ='DES-AB-Internat'!C31 -> 45954 | N31: ='DES-AB-CHARTRES'!C31 -> 45627 | O31: ='DES-AB-VERNOUILLET'!C31 -> 45627 | P31: ='DES-AB-2SAI'!C31 -> 0 | R31: ='CMPP-DREUX'!C31 -> 45698 | T31: ='CMPP-CHARTRES'!C31 -> 45964 | U31: ='CMPP-CHATEAUDUN'!C31 -> 45200 | W31: ='DITEP-SENONCHES'!C31 -> 0 | X31: ='DITEP-MORANCEZ'!C31 -> 45536 | Z31: ='PISP-DDAISP-ESATHM'!C31 -> 45736 | AA31: ='PIPSP habitat inclusif'!C31 -> X Pas d'obligation | AB31: X
A32: Personnel EPI | B32: formation | C32: =CDLA!C32 -> 0 | E32: ='DAME-AF-SEES'!C32 -> 46057 | F32: ='DAME-AF-SIPFP'!C32 -> 46057 | G32: ='DAME-AF+GEM-Clémenceau'!C32 -> 43556 | H32: ='DAME-AF-Internat'!C32 -> 43556 | J32: ='DAME-BD'!C32 -> 45751 | L32: ='DES-AB-NLR'!C32 -> 46057 | M32: ='DES-AB-Internat'!C32 -> 45952 | N32: ='DES-AB-CHARTRES'!C32 -> 45627 | O32: ='DES-AB-VERNOUILLET'!C32 -> 45627 | P32: ='DES-AB-2SAI'!C32 -> 45627 | R32: ='CMPP-DREUX'!C32 -> 45383 | T32: ='CMPP-CHARTRES'!C32 -> 45757 | U32: ='CMPP-CHATEAUDUN'!C32 -> 45757 | W32: ='DITEP-SENONCHES'!C32 -> 45943 | X32: ='DITEP-MORANCEZ'!C32 -> 45943 | Z32: ='PISP-DDAISP-ESATHM'!C32 -> 45701 | AA32: ='PIPSP habitat inclusif'!C32 -> X Pas d'obligation | AB32: X
A33: Manipulation SSI | B33: formation | C33: =CDLA!C33 -> 0 | E33: ='DAME-AF-SEES'!C33 -> 0 | F33: ='DAME-AF-SIPFP'!C33 -> 0 | G33: ='DAME-AF+GEM-Clémenceau'!C33 -> 1 | H33: ='DAME-AF-Internat'!C33 -> 45931 | J33: ='DAME-BD'!C33 -> 45960 | L33: ='DES-AB-NLR'!C33 -> 45717 | M33: ='DES-AB-Internat'!C33 -> 46087 | N33: ='DES-AB-CHARTRES'!C33 -> 45911 | O33: ='DES-AB-VERNOUILLET'!C33 -> 45911 | P33: ='DES-AB-2SAI'!C33 -> 0 | R33: ='CMPP-DREUX'!C33 -> 45536 | T33: ='CMPP-CHARTRES'!C33 -> 45757 | U33: ='CMPP-CHATEAUDUN'!C33 -> 45757 | W33: ='DITEP-SENONCHES'!C33 -> 45231 | X33: ='DITEP-MORANCEZ'!C33 -> 45383 | Z33: ='PISP-DDAISP-ESATHM'!C33 -> 45444 | AA33: ='PIPSP habitat inclusif'!C33 -> X Pas d'obligation | AB33: X
A34: Personnel habilité ELEC | B34: formation | C34: =CDLA!C34 -> X | E34: ='DAME-AF-SEES'!C34 -> 45771 | F34: ='DAME-AF-SIPFP'!C34 -> 45771 | G34: ='DAME-AF+GEM-Clémenceau'!C34 -> 45771 | H34: ='DAME-AF-Internat'!C34 -> 45771 | J34: ='DAME-BD'!C34 -> 45385 | L34: ='DES-AB-NLR'!C34 -> 45383 | M34: ='DES-AB-Internat'!C34 -> 45383 | N34: ='DES-AB-CHARTRES'!C34 -> 45383 | O34: ='DES-AB-VERNOUILLET'!C34 -> 45383 | P34: ='DES-AB-2SAI'!C34 -> 45383 | R34: ='CMPP-DREUX'!C34 -> X | T34: ='CMPP-CHARTRES'!C34 -> 45770 | U34: ='CMPP-CHATEAUDUN'!C34 -> 45770 | W34: ='DITEP-SENONCHES'!C34 -> 45770 | X34: ='DITEP-MORANCEZ'!C34 -> 45770 | Z34: ='PISP-DDAISP-ESATHM'!C34 -> X | AA34: ='PIPSP habitat inclusif'!C34 -> X Pas d'obligation | AB34: X
A35: Diag accessibilité handicapes | C35: =IF(CDLA!C35="", "", CDLA!C35) | E35: =IF('DAME-AF-SEES'!C35="", "", 'DAME-AF-SEES'!C35) | F35: =IF('DAME-AF-SIPFP'!C35="","",'DAME-AF-SIPFP'!C35) | G35: =IF('DAME-AF+GEM-Clémenceau'!C35="","",'DAME-AF+GEM-Clémenceau'!C35) | H35: =IF('DAME-AF-Internat'!C35="","",'DAME-AF-Internat'!C35) -> X Pas d'obligation | J35: =IF('DAME-BD'!C35="", "", 'DAME-BD'!C35) -> 45979 | L35: =IF('DES-AB-NLR'!C35="", "", 'DES-AB-NLR'!C35) -> 44256 | M35: =IF('DES-AB-Internat'!C35="", "", 'DES-AB-Internat'!C35) | N35: =IF('DES-AB-CHARTRES'!C35="", "", 'DES-AB-CHARTRES'!C35) | O35: =IF('DES-AB-VERNOUILLET'!C35="", "", 'DES-AB-VERNOUILLET'!C35) | P35: =IF('DES-AB-2SAI'!C35="", "", 'DES-AB-2SAI'!C35) -> 0 | R35: =IF('CMPP-DREUX'!C35="", "", 'CMPP-DREUX'!C35) -> 0 | T35: =IF('CMPP-CHARTRES'!C35="", "", 'CMPP-CHARTRES'!C35) -> 42675 | U35: =IF('CMPP-CHATEAUDUN'!C35="", "", 'CMPP-CHATEAUDUN'!C35) | W35: =IF('DITEP-SENONCHES'!C35="", "", 'DITEP-SENONCHES'!C35) -> 0 | X35: =IF('DITEP-MORANCEZ'!C35="", "", 'DITEP-MORANCEZ'!C35) | Z35: =IF('PISP-DDAISP-ESATHM'!C35="", "", 'PISP-DDAISP-ESATHM'!C35) -> 45261 | AA35: =IF('PIPSP habitat inclusif'!C35="", "", 'PIPSP habitat inclusif'!C35) -> X Pas d'obligation
A36: Diag technique amiante et plombs | B36: tous les 3ans si présence | C36: =CDLA!C36 -> 42856 | E36: ='DAME-AF-SEES'!C36 -> 45444 | F36: ='DAME-AF-SIPFP'!C36 -> 45444 | G36: ='DAME-AF+GEM-Clémenceau'!C36 -> 0 | H36: ='DAME-AF-Internat'!C36 -> X | J36: ='DAME-BD'!C36 -> X | L36: ='DES-AB-NLR'!C36 -> 42644 | M36: ='DES-AB-Internat'!C36 -> 39326 | N36: ='DES-AB-CHARTRES'!C36 -> 0 | O36: ='DES-AB-VERNOUILLET'!C36 -> 0 | P36: ='DES-AB-2SAI'!C36 -> 0 | R36: ='CMPP-DREUX'!C36 -> 0 | T36: ='CMPP-CHARTRES'!C36 -> X | U36: ='CMPP-CHATEAUDUN'!C36 -> 0 | W36: ='DITEP-SENONCHES'!C36 -> 41821 | X36: X | Z36: ='PISP-DDAISP-ESATHM'!C36 -> 0 | AA36: ='PIPSP habitat inclusif'!C36 -> X Pas d'obligation | AB36: X
A37: Procédures de coupures GAZ | C37: =CDLA!C37 -> X | E37: ='DAME-AF-SEES'!C37 -> 0 | F37: ='DAME-AF-SIPFP'!C37 -> 0 | G37: ='DAME-AF+GEM-Clémenceau'!C37 -> 0 | H37: ='DAME-AF-Internat'!C37 -> X | J37: ='DAME-BD'!C37 -> X | L37: ='DES-AB-NLR'!C37 -> 0 | M37: ='DES-AB-Internat'!C37 -> X | N37: ='DES-AB-CHARTRES'!C37 -> 45809 | O37: ='DES-AB-VERNOUILLET'!C37 -> 44562 | P37: ='DES-AB-2SAI'!C37 -> X | R37: ='CMPP-DREUX'!C37 -> 44409 | T37: ='CMPP-CHARTRES'!C37 -> X | U37: ='CMPP-CHATEAUDUN'!C37 -> X | W37: ='DITEP-SENONCHES'!C37 -> 0 | X37: ='DITEP-MORANCEZ'!C37 -> 0 | Z37: ='PISP-DDAISP-ESATHM'!C37 -> 45796 | AA37: ='PIPSP habitat inclusif'!C37 -> X Pas d'obligation | AB37: X
A38: Procédures de coupures ELEC | C38: =CDLA!C38 -> 45832 | E38: ='DAME-AF-SEES'!C38 -> 0 | F38: ='DAME-AF-SIPFP'!C38 -> 0 | G38: ='DAME-AF+GEM-Clémenceau'!C38 -> 0 | H38: ='DAME-AF-Internat'!C38 -> X | J38: ='DAME-BD'!C38 -> 0 | L38: ='DES-AB-NLR'!C38 -> 0 | M38: ='DES-AB-Internat'!C38 -> 0 | N38: ='DES-AB-CHARTRES'!C38 -> 45809 | O38: ='DES-AB-VERNOUILLET'!C38 -> 44562 | P38: ='DES-AB-2SAI'!C38 -> 44470 | R38: ='CMPP-DREUX'!C38 -> 44409 | T38: ='CMPP-CHARTRES'!C38 -> 0 | U38: ='CMPP-CHATEAUDUN'!C38 -> 0 | W38: ='DITEP-SENONCHES'!C38 -> 0 | X38: ='DITEP-MORANCEZ'!C38 -> 0 | Z38: ='PISP-DDAISP-ESATHM'!C38 -> 45796 | AA38: ='PIPSP habitat inclusif'!C38 -> X Pas d'obligation | AB38: X
A39: Procédures de coupures EAU | C39: =CDLA!C39 -> 45832 | E39: ='DAME-AF-SEES'!C39 -> 0 | F39: ='DAME-AF-SIPFP'!C39 -> 0 | G39: ='DAME-AF+GEM-Clémenceau'!C39 -> 0 | H39: ='DAME-AF-Internat'!C39 -> X | J39: ='DAME-BD'!C39 -> 0 | L39: ='DES-AB-NLR'!C39 -> 45809 | M39: ='DES-AB-Internat'!C39 -> 0 | N39: ='DES-AB-CHARTRES'!C39 -> 45809 | O39: ='DES-AB-VERNOUILLET'!C39 -> 44562 | P39: ='DES-AB-2SAI'!C39 -> 44470 | R39: ='CMPP-DREUX'!C39 -> 44409 | T39: ='CMPP-CHARTRES'!C39 -> 0 | U39: ='CMPP-CHATEAUDUN'!C39 -> 0 | W39: ='DITEP-SENONCHES'!C39 -> 0 | X39: ='DITEP-MORANCEZ'!C39 -> 0 | Z39: ='PISP-DDAISP-ESATHM'!C39 -> 45796 | AA39: ='PIPSP habitat inclusif'!C39 -> X Pas d'obligation | AB39: X
A40: Procédures évacuation incendie | C40: =CDLA!C40 -> 45832 | E40: ='DAME-AF-SEES'!C40 -> 46007 | F40: ='DAME-AF-SIPFP'!C40 -> 46007 | G40: ='DAME-AF+GEM-Clémenceau'!C40 -> 45636 | H40: ='DAME-AF-Internat'!C40 -> X | J40: ='DAME-BD'!C40 -> 45812 | L40: ='DES-AB-NLR'!C40 -> 45574 | M40: ='DES-AB-Internat'!C40 -> 45574 | N40: ='DES-AB-CHARTRES'!C40 -> 45574 | O40: ='DES-AB-VERNOUILLET'!C40 -> 45574 | P40: ='DES-AB-2SAI'!C40 -> 45574 | R40: ='CMPP-DREUX'!C40 -> 45812 | T40: ='CMPP-CHARTRES'!C40 -> 45901 | U40: ='CMPP-CHATEAUDUN'!C40 -> 45292 | W40: ='DITEP-SENONCHES'!C40 -> 45811 | X40: ='DITEP-MORANCEZ'!C40 -> 45536 | Z40: ='PISP-DDAISP-ESATHM'!C40 -> 45846 | AA40: ='PIPSP habitat inclusif'!C40 -> X Pas d'obligation | AB40: X
...

Sheet CDLA
A1: Objet | C1: État registre de sécurité SHAREPOINT | D1: Remarques | E1: état et commentaire de la direction
A3: Commission de sécurité | B3: PV | C3: X
A4: Triennale | B4: contrôle | C4: X
A5: alarme incendie | B5: entretien | D5: pas de système d'alarme incendie, je vous conseil d'en mettre un en place (NEUTRONIC propose des systèmes très efficaces)
A6: Extinteurs | B6: entretien | C6: 45590 | D6: les rapports arrivent au siège (demander à EUROFEU de signer le registre du CDLA)
A7: Désenfumage | B7: entretien | C7: X
A8: Exercices incendie | B8: 1 | C8: 45575 | D8: scanner le rapport du siège et le joindre à l'annexe
B9: 2 | C9: 45744 | D9: scanner le rapport du siège et le joindre à l'annexe
A10: Exercices PPMS | B10: 1 | D10: à mettre en place avec le siège, faire RETEX, classer dans l'annexe et attente retour scanné
B11: 2
A12: calage des dates d'exercices de l'année scolaire | B12: date butoir fin Août | C12: 45444 | D12: mettre en place les dates d'exercices en lien avec le siège
A13: Électricité | B13: vérification | C13: 45301 | D13: appeler SOCOTEC pour rendre RDV rapidement
A14: blocs de secours (internat mensuel) | B14: vérification | C14: X
A15: Ascenseur | B15: entretien | C15: X
B16: vérification | C16: X
A17: Quinquenale | B17: contrôle | C17: X
A18: Élévateur | B18: entretien | C18: X
B19: vérification | C19: X
A20: Portail | B20: vérification | C20: X
A21: Groupe électrogène | B21: entretien | C21: X
A22: Jeux exterieur | B22: vérification | C22: X
A23: Mur d'escalade | B23: vérification | C23: X
A24: Chaufferie | B24: ramonage | C24: X
A25: Disconnecteur | B25: vérification | C25: X
A26: Gaz | B26: vérification | C26: X
A27: CTA | B27: entretien | C27: X
B28: vérification | C28: X
A29: Plans d'intervention | C29: 45832 | D29: à lier à la procédure incendie
A30: Plans des abords extérieur (point de rassemblement et circulation) | C30: 45832 | D30: à lier à la procédure incendie
A31: Personnel SST | B31: formation | D31: URGENT pas de formation à jour (seront intégré aux formation de DREUX) (attente du retour des feuilles de formation)
A32: Personnel EPI | B32: formation | D32: URGENT pas de formation à jour (seront intégré aux formation de DREUX) (attente du retour des feuilles de formation)
A33: Manipulation SSI | B33: formation | D33: pas de formation à jour (seront intégré aux formation de DREUX) (attente du retour des feuilles de formation)
A34: Personnel habilité ELEC | B34: formation | C34: X | D34: géré par les factos du siège
A35: Diag accessibilité handicapes | D35: je vois avec Émilie si un diag à été fait en même temps que le siège
A36: Diag technique amiante et plombs | B36: tous les 3ans si présence | C36: 42856 | D36: diag effectué avec le siège lors de l'achat (présence d'amiante de catégorie A qui nécessite un recontrôle tous les 3ans)
A37: Procédures de coupures GAZ | C37: X
A38: Procédures de coupures ELEC | C38: 45832
A39: Procédures de coupures EAU | C39: 45832
A40: Procédures évacuation incendie | C40: 45832 | D40: mettre cette procédure à chaque issues de secours
A41: Procédures ouverture portail | C41: X
...

Sheet DAME-AF-SEES
A1: Objet | C1: État registre de sécurité SHAREPOINT | D1: DAME AF SEES Retour suite réunion de sécurité du 2025/05/02 | E1: état et commentaire de la direction
A3: Commission de sécurité | B3: PV | C3: Présent | D3: 17/02/2000 Catégorie5 TypeR voir si les prescriptions de la sous commission de sécurité sont bien levées
A4: Triennale | B4: contrôle | C4: X
A5: alarme incendie | B5: entretien | C5: 46041 | D5: remplacer DM dans la cuisine + suite passage ASGAR : alarme HS dans l'administration à remplacer | E5: contrôle fait le 19/01/26 , un déclencheur dans la cuisine NFP
A6: Extinteurs | B6: entretien | C6: 45624 | E6: Manuel :fait le 07/01/2026 attente PV
A7: Désenfumage | B7: entretien | C7: X
A8: Exercices incendie | B8: 1 | C8: 45923
B9: 2 | C9: 45803
A10: Exercices PPMS | B10: 1 | C10: 45943
B11: 2
A12: calage des dates d'exercices de l'année scolaire | B12: date butoir fin Août | C12: 45809 | D12: incendie: 23/09/2025 + 20/03/2026 PPMS: 13/10/2025 + 13/04/2026
A13: Électricité | B13: vérification | C13: 46041 | D13: lever les non conformités "attention la remarque 4 est un dangers de mort!!!!"
A14: blocs de secours (internat mensuel) | B14: vérification | C14: X
A15: Ascenseur | B15: entretien | C15: X
B16: vérification | C16: X
A17: Quinquenale | B17: contrôle | C17: X
A18: Élévateur | B18: entretien | C18: X
B19: vérification | C19: X
A20: Portail | B20: vérification | C20: 45701 | E20: Manuel: fait le 19/01/26 attente PV
A21: Groupe électrogène | B21: entretien | C21: X | E21: Manuel : pas de GE sur la SEES
A22: Jeux exterieur | B22: vérification | C22: 45686 | D22: lever les non conformités | E22: Manuel : contrôle SOCOTEC fait le 02/02/26 attente PV
A23: Mur d'escalade | B23: vérification | C23: X
A24: Chaufferie | B24: ramonage | C24: 45751 | E24: demande faite à DALKYA le 24/11/25
A25: Disconnecteur | B25: vérification | C25: 45912
A26: Gaz | B26: vérification | C26: 45692
A27: CTA | B27: entretien | C27: X
B28: vérification | C28: X
A29: Plans d'intervention | C29: 45989 | D29: mettre dans bannette aux issus de secours
A30: Plans des abords extérieur (point de rassemblement et circulation) | D30: à créer, classer dans l'annexe, mettre dans bannette aux issus de secours, attente retour scanné | E30: Manuel: document déjà sur sharepoint
A31: Personnel SST | B31: formation | C31: 45698 | D31: afficher la liste des personnes formées aux issues de secours | E31: Manuel : nouvelle liste envoyée le 11/12/25
A32: Personnel EPI | B32: formation | C32: 46057 | D32: afficher la liste aux issues de secours | E32: Manuel : nouvelle liste envoyée le 11/12/25
A33: Manipulation SSI | B33: formation | D33: mettre en place formation avec une liste tenue à jour, afficher, classer dans l'annexe et attente retour scanné de l'ensemble des formés
A34: Personnel habilité ELEC | B34: formation | C34: 45771
A35: Diag accessibilité handicapes | D35: voir si un document à été fait, le classer dans l'annexe et attente retour scanné
A36: Diag technique amiante et plombs | B36: tous les 3ans si présence | C36: 45444
A37: Procédures de coupures GAZ | D37: à faire pour G.GATEAU
A38: Procédures de coupures ELEC | D38: à faire pour G.GATEAU
A39: Procédures de coupures EAU | D39: à faire pour G.GATEAU
A40: Procédures évacuation incendie | C40: 46007 | D40: à mettre dans les petites bannettes à chaque issus de secours
A41: Procédures ouverture portail | C41: 46002
...

Sheet DAME-AF-SIPFP
A1: Objet | C1: État registre de sécurité SHAREPOINT | D1: DAME AF SIPFP Retour suite réunion de sécurité du 02/05/2025 | E1: état et commentaire de la direction
A3: Commission de sécurité | B3: PV | C3: Présent | D3: 17/02/2000 Catégorie5 TypeR voir si les prescription de la sous commission de sécurité sont bien levées
A4: Triennale | B4: contrôle | C4: X
A5: alarme incendie | B5: entretien | C5: 46028
A6: Extinteurs | B6: entretien | C6: 45597 | E6: Manuel: fait le 07/01/2026 attente PV
A7: Désenfumage | B7: entretien | C7: X
A8: Exercices incendie | B8: 1 | C8: 45923
B9: 2 | C9: 45678
A10: Exercices PPMS | B10: 1 | C10: 45943
B11: 2
A12: calage des dates d'exercices de l'année scolaire | B12: date butoir fin Août | C12: 45809 | D12: Incendie : 23/09/2025 + 20/03/2026 PPMS : 13/10/2025 + 13/04/2026
A13: Électricité | B13: vérification | C13: 46041 | D13: lever les non-conformités
A14: blocs de secours (internat mensuel) | B14: vérification | C14: X
A15: Ascenseur | B15: entretien | C15: X
B16: vérification | C16: X
A17: Quinquenale | B17: contrôle | C17: X
A18: Élévateur | B18: entretien | C18: X
B19: vérification | C19: X
A20: Portail | B20: vérification | C20: 45701 | D20: lever non-conformité (barre palpeuse à mettre en place) | E20: Manuel: fait le 19/01/26 attente PV
A21: Groupe électrogène | B21: entretien | C21: X | E21: Manuel : Devis reçu le 08/12/2025
A22: Jeux exterieur | B22: vérification | C22: X | D22: arrondir les angles des pieds de l'ancienne table de ping pong | E22: Manuel : fait table entièrement démontée
A23: Mur d'escalade | B23: vérification | C23: X
A24: Chaufferie | B24: ramonage | C24: 45751
A25: Disconnecteur | B25: vérification | C25: X
A26: Gaz | B26: vérification | C26: 46043 | D26: lever les non-conformités (panneautage à refaire) ATTENTION déjà identifié en 2025 | E26: Manuel : vitre supprimée
A27: CTA | B27: entretien | C27: X
B28: vérification | C28: X
A29: Plans d'intervention | C29: 45658 | D29: classer dans l'annexe, mettre dans bannette aux issus de secours
A30: Plans des abords extérieur (point de rassemblement et circulation) | C30: 45658
A31: Personnel SST | B31: formation | C31: 45698 | E31: Manuel : nouvelle liste envoyée le 11/12/25
A32: Personnel EPI | B32: formation | C32: 46057 | D32: afficher la liste à chaque issus de secours | E32: Manuel : nouvelle liste envoyée le 11/12/25
A33: Manipulation SSI | B33: formation | D33: mettre en place formation, afficher, classer dans l'annexe et attente retour scanné de l'ensemble des formés
A34: Personnel habilité ELEC | B34: formation | C34: 45771
A35: Diag accessibilité handicapes | D35: voir si un document à été fait, le classer dans l'annexe et attente retour scanné
A36: Diag technique amiante et plombs | B36: tous les 3ans si présence | C36: 45444
A37: Procédures de coupures GAZ | D37: à faire pour G.GATEAU
A38: Procédures de coupures ELEC | D38: à faire pour G.GATEAU
A39: Procédures de coupures EAU | D39: à faire pour G.GATEAU
A40: Procédures évacuation incendie | C40: 46007 | D40: à mettre dans les petites bannettes à chaque issus de secours
A41: Procédures ouverture portail | C41: 46002 | E41: Manuel : envoyée le 10/12/25
...

Sheet DAME-AF+GEM-Clémenceau
A1: Objet | C1: État registre de sécurité SHAREPOINT | D1: DAME AF Clémenceau Retour suite réunion de sécurité du 02/05/2025 | E1: état et commentaire de la direction
A3: Commission de sécurité | B3: PV | C3: X
A4: Triennale | B4: contrôle | C4: X
A5: alarme incendie | B5: entretien | C5: 45988
A6: Extinteurs | B6: entretien | C6: 45614 | E6: fait le 08/10/2025 société EUROFEU
A7: Désenfumage | B7: entretien | C7: X
A8: Exercices incendie | B8: 1 | C8: 45923
B9: 2 | C9: 45680
A10: Exercices PPMS | B10: 1 | C10: 45943
B11: 2
A12: calage des dates d'exercices de l'année scolaire | B12: date butoir fin Août | C12: 45809 | D12: Incendie : 23/09/2025 + 20/03/2026 PPMS : 13/10/2025 + 13/04/2026
A13: Électricité | B13: vérification | C13: 46041 | E13: Manuel: fait le 19/01/26 attente PV
A14: blocs de secours (internat mensuel) | B14: vérification | C14: X
A15: Ascenseur | B15: entretien | C15: X
B16: vérification | C16: X
A17: Quinquenale | B17: contrôle | C17: X
A18: Élévateur | B18: entretien | C18: X
B19: vérification | C19: X
A20: Portail | B20: vérification | C20: X
A21: Groupe électrogène | B21: entretien | C21: X
A22: Jeux exterieur | B22: vérification | C22: X
A23: Mur d'escalade | B23: vérification | C23: X
A24: Chaufferie | B24: ramonage | C24: 1 | D24: mettre en place un contrat d'entretien au minimum annuelle
A25: Disconnecteur | B25: vérification | C25: X
A26: Gaz | B26: vérification | C26: X
A27: CTA | B27: entretien | C27: X
B28: vérification | C28: X
A29: Plans d'intervention | D29: à créer, classer dans l'annexe, mettre dans bannette aux issus de secours, attente retour scanné
A30: Plans des abords extérieur (point de rassemblement et circulation) | D30: à créer, classer dans l'annexe, mettre dans bannette aux issus de secours, attente retour scanné | E30: Manuel: document déjà sur sharepoint
A31: Personnel SST | B31: formation | C31: 1 | D31: il faut faire le point avec Mme PROFETI, afficher aux issus de secours, à classer dans l'annexe et attente retour scanné
A32: Personnel EPI | B32: formation | C32: 43556 | D32: remettre à jour les formations et afficher la liste
A33: Manipulation SSI | B33: formation | C33: 1 | D33: mettre en place formation, afficher, classer dans l'annexe et attente retour scanné de l'ensemble des formés
A34: Personnel habilité ELEC | B34: formation | C34: 45771
A35: Diag accessibilité handicapes
A36: Diag technique amiante et plombs | B36: tous les 3ans si présence | D36: voir rapport diag de l'achat du bâtiment
A37: Procédures de coupures GAZ | D37: à faire pour G.GATEAU
A38: Procédures de coupures ELEC | D38: à faire pour G.GATEAU
A39: Procédures de coupures EAU | D39: à faire pour G.GATEAU
A40: Procédures évacuation incendie | C40: 45636 | D40: mettre en place dans des petites bannettes à chaque issus de secours
A41: Procédures ouverture portail | C41: X
...

Sheet DAME-AF-Internat
A1: Objet | C1: État registre de sécurité SHAREPOINT | D1: DAME AF Internat Retour suite réunion de sécurité du 02/05/2025 | E1: état et commentaire de la direction
A3: Commission de sécurité | B3: PV | C3: X | D3: géré par DES AB Catégorie4 TypeJ
A4: Triennale | B4: contrôle | C4: X | D4: géré par DES AB
A5: alarme incendie | B5: entretien | C5: X | D5: géré par DES AB
A6: Extinteurs | B6: entretien | C6: X | D6: géré par DES AB
A7: Désenfumage | B7: entretien | C7: X | D7: géré par DES AB
A8: Exercices incendie | B8: 1 | C8: 45931
B9: 2 | C9: 46087
A10: Exercices PPMS | B10: 1 | C10: 45931
B11: 2 | C11: 46146
A12: calage des dates d'exercices de l'année scolaire | B12: date butoir fin Août | C12: 45809 | D12: Incendie : 01/10/2025 + 06/03/2026 PPMS : 08/10/2025 + 08/04/2026
A13: Électricité | B13: vérification | C13: 45757 | D13: lever les non conformités
A14: blocs de secours (internat mensuel) | B14: vérification | C14: X | D14: géré par DES AB
A15: Ascenseur | B15: entretien | C15: X
B16: vérification | C16: X
A17: Quinquenale | B17: contrôle | C17: X
A18: Élévateur | B18: entretien | C18: X
B19: vérification | C19: X
A20: Portail | B20: vérification | C20: X
A21: Groupe électrogène | B21: entretien | C21: X
A22: Jeux exterieur | B22: vérification | C22: X
A23: Mur d'escalade | B23: vérification | C23: X
A24: Chaufferie | B24: ramonage | C24: X
A25: Disconnecteur | B25: vérification | C25: X
A26: Gaz | B26: vérification | C26: X
A27: CTA | B27: entretien | C27: X
B28: vérification | C28: X
A29: Plans d'intervention | C29: X | D29: géré par DES AB
A30: Plans des abords extérieur (point de rassemblement et circulation) | C30: X | D30: géré par DES AB
A31: Personnel SST | B31: formation | D31: formation planifié au 24/10/2025 mais veilleur de nuit en arrêt maladie
A32: Personnel EPI | B32: formation | C32: 43556 | D32: formation planifié au 22/10/2025 mais veilleur de nuit en arrêt maladie
A33: Manipulation SSI | B33: formation | C33: 45931 | D33: mettre une liste d'émargement en place
A34: Personnel habilité ELEC | B34: formation | C34: 45771
A35: Diag accessibilité handicapes | C35: X Pas d'obligation
A36: Diag technique amiante et plombs | B36: tous les 3ans si présence | C36: X
A37: Procédures de coupures GAZ | C37: X
A38: Procédures de coupures ELEC | C38: X
A39: Procédures de coupures EAU | C39: X
A40: Procédures évacuation incendie | C40: X | D40: penser à sensibiliser chaque personne qui arrive dans l'établissement par le référent sécurité (une procédure commune du secteur PSM2S est à imaginer)
A41: Procédures ouverture portail | C41: X
...

Sheet DAME-BD
A1: Objet | C1: État registre de sécurité SHAREPOINT | D1: DAME BD Retour suite réunion de sécurité du 27/05/2025 | E1: état et commentaire de la direction
A3: Avis préliminaire de la commision de sécurité | B3: PV | C3: X | D3: 44409
A4: Triennale | B4: contrôle | C4: X
A5: alarme incendie | B5: vérification | C5: 45728
A6: Extinteurs | B6: entretien | C6: 45505
A7: Désenfumage | B7: entretien | C7: X
A8: Exercices incendie | B8: 1 | C8: 45930
B9: 2 | C9: 45744
A10: Exercices PPMS | B10: 1 | C10: 45943
B11: 2 | C11: 45671
A12: calage des dates d'exercices de l'année scolaire | B12: date butoir fin Août | C12: 45809 | D12: Incendie : 23/09/2025 + 12/02/2026 . PPMS : 06/10/2025+ 07/04/2026
A13: Électricité | B13: vérification | C13: 46077
A14: blocs de secours (internat mensuel) | B14: vérification | C14: X
A15: Ascenseur | B15: entretien | C15: X
B16: vérification | C16: X
A17: Quinquenale | B17: contrôle | C17: X
A18: Élévateur | B18: entretien | C18: X
B19: vérification | C19: X
A20: Portail | B20: vérification | C20: X
A21: Groupe électrogène | B21: entretien | C21: X
A22: Jeux exterieur | B22: vérification | C22: 45821
A23: Mur d'escalade | B23: vérification | C23: X
A24: Chaufferie | B24: ramonage | C24: X
A25: Disconnecteur | B25: vérification | C25: X | D25: géré par le siège
A26: Gaz | B26: vérification | C26: X
A27: CTA | B27: entretien | D27: impossibilité de mise en place de contrat d'entretien par DALKIA car attente de date de prise en main par EIFFAGE | E27: un courrier recommandé a été envoyer au 17/09/2025 avec un retour de leur part, mais pas d'intervention à ce jour (17/11/2025) (prochaine étape si non retour au 03/12/2025 appel à un cabinet d'avocat.
B28: vérification | D28: vérification faite le 27/11 attente du rapport scanné
A29: Plans d'intervention | C29: 45812 | D29: attente des plans conformes
A30: Plans des abords extérieur (point de rassemblement et circulation) | C30: 45804
A31: Personnel SST | B31: formation | C31: 45964
A32: Personnel EPI | B32: formation | C32: 45751
A33: Manipulation SSI | B33: formation | C33: 45960
A34: Personnel habilité ELEC | B34: formation | C34: 45385 | D34: fin d'habilitation pour Anthony 02/04/2027 pour Florian 09/12/2028
A35: Attestation accessibilité handicapes | C35: 45979
A36: Diag technique amiante et plombs | B36: tous les 3ans si présence | C36: X | D36: construit après 1997
A37: Procédures de coupures GAZ | C37: X
A38: Procédures de coupures ELEC | D38: envoyer la trame à Florian
A39: Procédures de coupures EAU | D39: envoyer la trame à Florian
A40: Procédures évacuation incendie | C40: 45812
A41: Procédures ouverture portail | C41: X
...

Sheet DES-AB-NLR
A1: Objet | C1: État registre de sécurité SHAREPOINT | D1: DES AB NLR Retour suite réunion de sécurité du | E1: état et commentaire de la direction
A3: Commission de sécurité | B3: PV | C3: X | D3: 35947
A4: Triennale | B4: contrôle | C4: X
A5: alarme incendie | B5: entretien | C5: 45717
A6: Extinteurs | B6: entretien | C6: 45689
A7: Désenfumage | B7: entretien | C7: 45689
A8: Exercices incendie | B8: 1 | C8: 45536 | D8: demande de nouvelle date faite le 15/01/2026 mettre en place les tableaux de présence pour les professionnels et mettre en place un responsable qui sortira la liste des usagers présent à chaque exercie PPMS et incendie
B9: 2 | C9: 45717
A10: Exercices PPMS | B10: 1 | C10: 45936
B11: 2 | C11: 46097
A12: calage des dates d'exercices de l'année scolaire | B12: date butoir fin Août | C12: 45809 | D12: incendie : 22/09/2025 + 09/03/2026 . PPMS : 06/10/2025 + 16/03/2026 / faire un point sur la mise en place au regard des exercice de l'année passée
A13: Électricité | B13: vérification | C13: 45897 | D13: lever les non conformitées devis transmis le 24/09/2025
A14: blocs de secours (internat mensuel) | B14: vérification | C14: X
A15: Ascenseur | B15: entretien | C15: X
B16: vérification | C16: X
A17: Quinquenale | B17: contrôle | C17: X
A18: Élévateur | B18: entretien | C18: X
B19: vérification | C19: X
A20: Portail | B20: vérification | C20: 45658
A21: Groupe électrogène | B21: entretien | C21: 45965
A22: Jeux exterieur | B22: vérification | C22: 45658
A23: Mur d'escalade | B23: vérification | C23: 45413 | D23: mail de proposition de date de d'intervention envoyé le 04/04/2025 avec validation du devis remplacement des cordes (mur non utilisé car plus de professeur depuis septembre)
A24: Chaufferie | B24: ramonage | C24: 45845
A25: Disconnecteur | B25: vérification | C25: 45910
A26: Gaz | B26: vérification | C26: 45924
A27: CTA | B27: entretien | C27: X
B28: vérification | C28: X
A29: Plans d'intervention | C29: 45809
A30: Plans des abords extérieur (point de rassemblement et circulation) | C30: 45809
A31: Personnel SST | B31: formation | C31: 45627
A32: Personnel EPI | B32: formation | C32: 46057
A33: Manipulation SSI | B33: formation | C33: 45717
A34: Personnel habilité ELEC | B34: formation | C34: 45383
A35: Diag accessibilité handicapes | C35: 44256
A36: Diag technique amiante et plombs | B36: tous les 3ans si présence | C36: 42644
A37: Procédures de coupures GAZ | D37: faire procédure
A38: Procédures de coupures ELEC | D38: faire procédure
A39: Procédures de coupures EAU | C39: 45809
A40: Procédures évacuation incendie | C40: 45574
A41: Procédures ouverture portail
...

Sheet DES-AB-Internat
A1: Objet | C1: État registre de sécurité SHAREPOINT | D1: DES AB internat Retour suite réunion de sécurité du 02/05/2025 | E1: état et commentaire de la direction
A3: Commission de sécurité | B3: PV | C3: 44986 | D3: contacter la mairie pour récuprer le rapport de la sous commision de sécurité et lever les prescription Catégorie 4 TypeJ
A4: Triennale | B4: contrôle | C4: 45047
A5: alarme incendie | B5: entretien | C5: 45981
A6: Extinteurs | B6: entretien | C6: 45712
A7: Désenfumage | B7: entretien | C7: 45712
A8: Exercices incendie | B8: 1 | C8: 45903
B9: 2 | C9: 46087
A10: Exercices PPMS | B10: 1 | C10: 45931
B11: 2 | C11: 46146
A12: calage des dates d'exercices de l'année scolaire | B12: date butoir fin Août | C12: 46174 | D12: Incendie : 03/09/2025 + 06/03/2026 PPMS : 08/10/2025 + 08/04/2026
A13: Électricité | B13: vérification | C13: 46121 | D13: Lever les remarques
A14: blocs de secours (internat mensuel) | B14: vérification | C14: 46030
A15: Ascenseur | B15: entretien | C15: X
B16: vérification | C16: X
A17: Quinquenale | B17: contrôle | C17: X
A18: Élévateur | B18: entretien | C18: X
B19: vérification | C19: X
A20: Portail | B20: vérification | C20: X
A21: Groupe électrogène | B21: entretien | C21: X
A22: Jeux exterieur | B22: vérification | C22: X
A23: Mur d'escalade | B23: vérification | C23: X
A24: Chaufferie | B24: ramonage | C24: X
A25: Disconnecteur | B25: vérification | C25: X
A26: Gaz | B26: vérification | C26: X
A27: CTA | B27: entretien | C27: X
B28: vérification | C28: X
A29: Plans d'intervention | C29: 45809
A30: Plans des abords extérieur (point de rassemblement et circulation) | C30: 45809
A31: Personnel SST | B31: formation | C31: 45954
A32: Personnel EPI | B32: formation | C32: 45952
A33: Manipulation SSI | B33: formation | C33: 46087
A34: Personnel habilité ELEC | B34: formation | C34: 45383
A35: Diag accessibilité handicapes
A36: Diag technique amiante et plombs | B36: tous les 3ans si présence | C36: 39326
A37: Procédures de coupures GAZ | C37: X
A38: Procédures de coupures ELEC
A39: Procédures de coupures EAU
A40: Procédures évacuation incendie | C40: 45574
A41: Procédures ouverture portail | C41: X
...

Sheet DES-AB-CHARTRES
A1: Objet | C1: État registre de sécurité SHAREPOINT | D1: DES AB CHARTRES Retour suite réunion de sécurité du | E1: état et commentaire de la direction
A3: Commission de sécurité | B3: PV | C3: NC
A4: Triennale | B4: contrôle | C4: X
A5: alarme incendie | B5: entretien | C5: 45911
A6: Extinteurs | B6: entretien | C6: 45689
A7: Désenfumage | B7: entretien | C7: 45689
A8: Exercices incendie | B8: 1 | C8: 45911
B9: 2 | C9: 46093
A10: Exercices PPMS | B10: 1 | C10: 45939
B11: 2 | C11: 45750
A12: calage des dates d'exercices de l'année scolaire | B12: date butoir fin Août | C12: 45809 | D12: incendie : 11/09/2025+ 12/03/2026 . PPMS : 09/10/2025 + 09/04/2026
A13: Électricité | B13: vérification | C13: 45366 | D13: appeler APAPVE pour voir ce qui se passe et prndre RDV
A14: blocs de secours (internat mensuel) | B14: vérification | C14: X
A15: Ascenseur | B15: entretien | C15: X
B16: vérification | C16: X
A17: Quinquenale | B17: contrôle | C17: X
A18: Élévateur | B18: entretien | C18: 45925 | D18: pas de rapport appeler ACIER et envoyer devis pour remplacement batterie
B19: vérification | C19: 45631 | D19: appeler APAPVE pour voir ce qui se passe et prndre RDV
A20: Portail | B20: vérification | C20: 45627 | D20: appeler APAPVE pour voir ce qui se passe et prndre RDV
A21: Groupe électrogène | B21: entretien | C21: X
A22: Jeux exterieur | B22: vérification | C22: X
A23: Mur d'escalade | B23: vérification | C23: X
A24: Chaufferie | B24: ramonage | C24: 1 | D24: mail envoyé à DALKIA le 25/11/2025 pour avoir un accès à l'espace client
A25: Disconnecteur | B25: vérification | C25: X
A26: Gaz | B26: vérification | C26: 45975 | D26: protéger canalisation cuivre GAZ sur les sorties de terre (2m) | E26: panneau déjà mis en place
A27: CTA | B27: entretien | C27: X
B28: vérification | C28: X
A29: Plans d'intervention | C29: 0 | D29: faire photo et mettre en ligne et sur procédure d'évacuation
A30: Plans des abords extérieur (point de rassemblement et circulation) | C30: 0 | D30: à faire Guillaume
A31: Personnel SST | B31: formation | C31: 45627 | D31: prochain recyclage 2026.12
A32: Personnel EPI | B32: formation | C32: 45627
A33: Manipulation SSI | B33: formation | C33: 45911 | D33: mettre en place une feuille d'émargement
A34: Personnel habilité ELEC | B34: formation | C34: 45383
A35: Diag accessibilité handicapes | D35: voir dans documents d'achat
A36: Diag technique amiante et plombs | B36: tous les 3ans si présence | C36: 0 | D36: voir dans documents d'achat
A37: Procédures de coupures GAZ | C37: 45809
A38: Procédures de coupures ELEC | C38: 45809
A39: Procédures de coupures EAU | C39: 45809
A40: Procédures évacuation incendie | C40: 45574 | D40: refaire la procédure en y mettant les plans d'interventions
A41: Procédures ouverture portail | D41: faire la procédure et la mettre en ligne
...

Sheet DES-AB-VERNOUILLET
A1: Objet | C1: État registre de sécurité SHAREPOINT | D1: DES AB VERNOUILLET Retour suite réunion de sécurité du | E1: état et commentaire de la direction
A3: Commission de sécurité | B3: PV | C3: NC
A4: Triennale | B4: contrôle | C4: X
A5: alarme incendie | B5: entretien | C5: 45911
A6: Extinteurs | B6: entretien | C6: 45689
A7: Désenfumage | B7: entretien | C7: X
A8: Exercices incendie | B8: 1 | C8: 45911
B9: 2 | C9: 46093
A10: Exercices PPMS | B10: 1 | C10: 45939
B11: 2 | C11: 45777
A12: calage des dates d'exercices de l'année scolaire | B12: date butoir fin Août | C12: 45809 | D12: incendie : 11/09/2025 + 12/03/2026 PPMS : 09/10/2025 + 09/04/2026
A13: Électricité | B13: vérification | C13: 45828 | D13: lever non conformités
A14: blocs de secours (internat mensuel) | B14: vérification | C14: X
A15: Ascenseur | B15: entretien | C15: X
B16: vérification | C16: X
A17: Quinquenale | B17: contrôle | C17: X
A18: Élévateur | B18: entretien | C18: X
B19: vérification | C19: X
A20: Portail | B20: vérification | C20: X
A21: Groupe électrogène | B21: entretien | C21: X
A22: Jeux exterieur | B22: vérification | C22: X
A23: Mur d'escalade | B23: vérification | C23: X
A24: Chaufferie | B24: ramonage | C24: 0 | D24: pas de rapport demander à PCS
A25: Disconnecteur | B25: vérification | C25: 0 | D25: voir si obligation avec APAVE
A26: Gaz | B26: vérification | C26: 0 | D26: faire faire un devis à APAVE
A27: CTA | B27: entretien | C27: X
B28: vérification | C28: X
A29: Plans d'intervention | C29: 45809
A30: Plans des abords extérieur (point de rassemblement et circulation) | C30: 0 | D30: à faire
A31: Personnel SST | B31: formation | C31: 45627 | D31: prochain recyclage 2026.12
A32: Personnel EPI | B32: formation | C32: 45627 | D32: à faire tous les ans
A33: Manipulation SSI | B33: formation | C33: 45911
A34: Personnel habilité ELEC | B34: formation | C34: 45383
A35: Diag accessibilité handicapes | D35: à faire
A36: Diag technique amiante et plombs | B36: tous les 3ans si présence | C36: 0 | D36: à faire
A37: Procédures de coupures GAZ | C37: 44562
A38: Procédures de coupures ELEC | C38: 44562
A39: Procédures de coupures EAU | C39: 44562
A40: Procédures évacuation incendie | C40: 45574
A41: Procédures ouverture portail | C41: X
...

Sheet DES-AB-2SAI
A1: Objet | C1: État registre de sécurité SHAREPOINT | D1: DES AB 2SAI Retour suite réunion de sécurité du | E1: état et commentaire de la direction
A3: Commission de sécurité | B3: PV | C3: NC
A4: Triennale | B4: contrôle | C4: X
A5: alarme incendie | B5: entretien | C5: 45911
A6: Extinteurs | B6: entretien | C6: 45689
A7: Désenfumage | B7: entretien | C7: X
A8: Exercices incendie | B8: 1 | C8: 45911
B9: 2 | C9: 46093
A10: Exercices PPMS | B10: 1 | C10: 45939
B11: 2 | C11: 45750
A12: calage des dates d'exercices de l'année scolaire | B12: date butoir fin Août | C12: 45809 | D12: incendie : 11/09/2025 + 12/03/2026 . PPMS : 09/10/2025 + 09/04/2026
A13: Électricité | B13: vérification | C13: 45715 | D13: voir remarque sur le différenciel 30mA + raccorder les terre sur un barreau de terre
A14: blocs de secours (internat mensuel) | B14: vérification | C14: X
A15: Ascenseur | B15: entretien | C15: X
B16: vérification | C16: X
A17: Quinquenale | B17: contrôle | C17: X
A18: Élévateur | B18: entretien | C18: X
B19: vérification | C19: X
A20: Portail | B20: vérification | C20: X
A21: Groupe électrogène | B21: entretien | C21: X
A22: Jeux exterieur | B22: vérification | C22: X
A23: Mur d'escalade | B23: vérification | C23: X
A24: Chaufferie | B24: ramonage | C24: X
A25: Disconnecteur | B25: vérification | C25: X
A26: Gaz | B26: vérification | C26: X
A27: CTA | B27: entretien | C27: X
B28: vérification | C28: X
A29: Plans d'intervention | C29: 0
A30: Plans des abords extérieur (point de rassemblement et circulation) | C30: 0
A31: Personnel SST | B31: formation | C31: 0 | D31: pas de formé à ce jour
A32: Personnel EPI | B32: formation | C32: 45627 | D32: à faire tous les ans
A33: Manipulation SSI | B33: formation | C33: 0 | D33: à faire lors de l'exercice incendie (préparer feuille d'émargement et scanner)
A34: Personnel habilité ELEC | B34: formation | C34: 45383
A35: Diag accessibilité handicapes | C35: 0 | D35: en location
A36: Diag technique amiante et plombs | B36: tous les 3ans si présence | C36: 0 | D36: en location
A37: Procédures de coupures GAZ | C37: X
A38: Procédures de coupures ELEC | C38: 44470
A39: Procédures de coupures EAU | C39: 44470
A40: Procédures évacuation incendie | C40: 45574
A41: Procédures ouverture portail | C41: X
...

Sheet CMPP-DREUX
A1: Objet | C1: État registre de sécurité SHAREPOINT | D1: CMPP DREUX Retour suite réunion de sécurité du 27/05/2025 | E1: état et commentaire de la direction
A3: Commission de sécurité | B3: NC | C3: NC
A4: Triennale | B4: contrôle | C4: X
A5: alarme incendie | B5: entretien | C5: 45566
A6: Extinteurs | B6: entretien | C6: 45536
A7: Désenfumage | B7: entretien | C7: X
A8: Exercices incendie | B8: 1 | C8: 45925
B9: 2 | C9: 0 | D9: obligation de 2 exercices par an
A10: Exercices PPMS | B10: 1 | C10: 0 | D10: pas d'exercice à ce jour en cour de mis en place (il faut faire 2 exercices par an : 1 pour intrusion et 1 pour confinement)
B11: 2 | C11: 0
A12: calage des dates d'exercices de l'année scolaire | B12: date butoir fin Août | C12: 45809 | D12: Incendie: deuxième semaine de septembre PPMS : en cour
A13: Électricité | B13: vérification | C13: 45898 | D13: attention des remarques dangeureuses sont à lever
A14: blocs de secours (internat mensuel) | B14: vérification | C14: X
A15: Ascenseur | B15: entretien | C15: X
B16: vérification | C16: X
A17: Quinquenale | B17: contrôle | C17: X
A18: Élévateur | B18: entretien | C18: X
B19: vérification | C19: X
A20: Portail | B20: vérification | C20: X
A21: Groupe électrogène | B21: entretien | C21: X
A22: Jeux exterieur | B22: vérification | C22: X
A23: Mur d'escalade | B23: vérification | C23: X
A24: Chaufferie | B24: ramonage | C24: 45352
A25: Disconnecteur | B25: vérification | C25: 45944 | D25: contacter PCS pour faire poser un disconnecteur
A26: Gaz | B26: vérification | C26: 45944
A27: CTA | B27: entretien | C27: X
B28: vérification | C28: X
A29: Plans d'intervention | C29: 45811
A30: Plans des abords extérieur (point de rassemblement et circulation) | C30: 45811
A31: Personnel SST | B31: formation | C31: 45698 | D31: pas de scan de la liste d'émargement donc j'ai mis un doc EXCEL
A32: Personnel EPI | B32: formation | C32: 45383 | D32: pas de scan de la liste d'émargement
A33: Manipulation SSI | B33: formation | C33: 45536
A34: Personnel habilité ELEC | B34: formation | C34: X | D34: gérer par le siège
A35: Diag accessibilité handicapes | C35: 0 | D35: pas de diag à ce jour. Attente de la ville le jour de la vente du bâtiment
A36: Diag technique amiante et plombs | B36: tous les 3ans si présence | C36: 0 | D36: pas de diag à ce jour. Attente de la ville le jour de la vente du bâtiment
A37: Procédures de coupures GAZ | C37: 44409 | D37: à jour
